<?xml version="1.0" ?>
<robot name="inspire_hand_left">

<link name="world"/>

<joint name="fixed" type="fixed">
  <origin xyz="0.2 0 0.2" rpy="0 0 1.57" />
  <parent link="world"/>
  <child link="base_link"/>
</joint>
    <link name="base_link">
        <inertial>
            <origin xyz="-0.000433277303987328 -3.54664423471128E-05 0.0599427668933796" rpy="0 0 0" />
            <mass value="0.841070778135659" />
            <inertia ixx="0.0017261110801622" ixy="2.52746264980217E-06" ixz="-3.67690303614961E-05" iyy="0.00170987405835604" iyz="1.67996364994424E-06" izz="0.000904023422915791" />
        </inertial>
        <visual>
            <origin xyz="0 0 0" rpy="0 0 0" />
            <geometry>
                <mesh filename="package://inspire_hand_description/meshes/left/base_Link.STL" />
            </geometry>
            <material name="">
                <color rgba="1 1 1 1" />
            </material>
        </visual>
        <collision>
            <origin xyz="0 0 0" rpy="0 0 0" />
            <geometry>
                <mesh filename="package://inspire_hand_description/meshes/left/base_Link.STL" />
            </geometry>
        </collision>
    </link>
    <link name="Link1">
        <inertial>
            <origin xyz="1.2226305431569E-08 0.0211079974844683 -0.0251854220842269" rpy="0 0 0" />
            <mass value="0.593563443690403" />
            <inertia ixx="0.00126614120341847" ixy="-1.294980943835E-08" ixz="-9.80120923066996E-09" iyy="0.00118168178300364" iyz="-0.00021121727444415" izz="0.00056135241627747" />
        </inertial>
        <visual>
            <origin xyz="0 0 0" rpy="0 0 0" />
            <geometry>
                <mesh filename="package://inspire_hand_description/meshes/left/Link1.STL" />
            </geometry>
            <material name="">
                <color rgba="1 1 1 1" />
            </material>
        </visual>
        <collision>
            <origin xyz="0 0 0" rpy="0 0 0" />
            <geometry>
                <mesh filename="package://inspire_hand_description/meshes/left/Link1.STL" />
            </geometry>
        </collision>
    </link>
    <joint name="joint1" type="revolute">
        <origin xyz="0 0 0.2405" rpy="0 0 0" />
        <parent link="base_link" />
        <child link="Link1" />
        <axis xyz="0 0 1" />
        <limit lower="-3.1" upper="3.1" effort="60" velocity="3.14" />
    </joint>
    <link name="Link2">
        <inertial>
            <origin xyz="0.152256463426163 4.75383656106654E-07 -0.00620260383607792" rpy="0 0 0" />
            <mass value="0.864175046869043" />
            <inertia ixx="0.00089150298478414" ixy="-2.23268489334765E-08" ixz="0.00156246461035015" iyy="0.00733754343083901" iyz="6.28110889329165E-09" izz="0.00697869103915473" />
        </inertial>
        <visual>
            <origin xyz="0 0 0" rpy="0 0 0" />
            <geometry>
                <mesh filename="package://inspire_hand_description/meshes/left/Link2.STL" />
            </geometry>
            <material name="">
                <color rgba="1 1 1 1" />
            </material>
        </visual>
        <collision>
            <origin xyz="0 0 0" rpy="0 0 0" />
            <geometry>
                <mesh filename="package://inspire_hand_description/meshes/left/Link2.STL" />
            </geometry>
        </collision>
    </link>
    <joint name="joint2" type="revolute">
        <origin xyz="0 0 0" rpy="1.5708 -1.5708 0" />
        <parent link="Link1" />
        <child link="Link2" />
        <axis xyz="0 0 1" />
        <limit lower="-2.268" upper="2.268" effort="60" velocity="3.14" />
    </joint>
    <link name="Link3">
        <inertial>
            <origin xyz="5.05312670989961E-06 -0.0595925663694732 0.010569069212336" rpy="0 0 0" />
            <mass value="0.289633681624654" />
            <inertia ixx="0.00063737100450158" ixy="-7.05261293649751E-08" ixz="-3.86643272239426E-08" iyy="0.00015648388095025" iyz="-0.00014461035994916" izz="0.000614178164773085" />
        </inertial>
        <visual>
            <origin xyz="0 0 0" rpy="0 0 0" />
            <geometry>
                <mesh filename="package://inspire_hand_description/meshes/left/Link3.STL" />
            </geometry>
            <material name="">
                <color rgba="1 1 1 1" />
            </material>
        </visual>
        <collision>
            <origin xyz="0 0 0" rpy="0 0 0" />
            <geometry>
                <mesh filename="package://inspire_hand_description/meshes/left/Link3.STL" />
            </geometry>
        </collision>
    </link>
    <joint name="joint3" type="revolute">
        <origin xyz="0.256 0 0" rpy="0 0 1.5708" />
        <parent link="Link2" />
        <child link="Link3" />
        <axis xyz="0 0 1" />
        <limit lower="-2.355" upper="2.355" effort="30" velocity="3.92" />
    </joint>
    <link name="Link4">
        <inertial>
            <origin xyz="1.15516617405898E-06 -0.0180424468598241 -0.0215394748352687" rpy="0 0 0" />
            <mass value="0.239419768320061" />
            <inertia ixx="0.000285938919722783" ixy="3.07101359163101E-09" ixz="-2.21994118981953E-09" iyy="0.000262727540304212" iyz="4.4236583260078E-05" izz="0.000119888082791859" />
        </inertial>
        <visual>
            <origin xyz="0 0 0" rpy="0 0 0" />
            <geometry>
                <mesh filename="package://inspire_hand_description/meshes/left/Link4.STL" />
            </geometry>
            <material name="">
                <color rgba="1 1 1 1" />
            </material>
        </visual>
        <collision>
            <origin xyz="0 0 0" rpy="0 0 0" />
            <geometry>
                <mesh filename="package://inspire_hand_description/meshes/left/Link4.STL" />
            </geometry>
        </collision>
    </link>
    <joint name="joint4" type="revolute">
        <origin xyz="0 -0.21 0" rpy="1.5708 0 0" />
        <parent link="Link3" />
        <child link="Link4" />
        <axis xyz="0 0 1" />
        <limit lower="-3.1" upper="3.1" effort="10" velocity="3.92" />
    </joint>
    <link name="Link5">
        <inertial>
            <origin xyz="3.19794786262152E-06 -0.0593808368101458 0.00736804250989326" rpy="0 0 0" />
            <mass value="0.218799761431678" />
            <inertia ixx="0.000350540363914072" ixy="-3.41781619975602E-08" ixz="-1.77056457224373E-08" iyy="0.000104927867487581" iyz="-7.82431228461971E-05" izz="0.000334482418423629" />
        </inertial>
        <visual>
            <origin xyz="0 0 0" rpy="0 0 0" />
            <geometry>
                <mesh filename="package://inspire_hand_description/meshes/left/Link5.STL" />
            </geometry>
            <material name="">
                <color rgba="1 1 1 1" />
            </material>
        </visual>
        <collision>
            <origin xyz="0 0 0" rpy="0 0 0" />
            <geometry>
                <mesh filename="package://inspire_hand_description/meshes/left/Link5.STL" />
            </geometry>
        </collision>
    </link>
    <joint name="joint5" type="revolute">
        <origin xyz="0 0 0" rpy="-1.5708 0 0" />
        <parent link="Link4" />
        <child link="Link5" />
        <axis xyz="0 0 1" />
        <limit lower="-2.233" upper="2.233" effort="10" velocity="3.92" />
    </joint>
    <link name="Link6">
        <inertial>
            <origin xyz="0.000714234511756999 -0.000396718732824521 -0.0126723660946126" rpy="0 0 0" />
            <mass value="0.0649018034311231" />
            <inertia ixx="2.02766547502765E-05" ixy="-1.32505200276849E-06" ixz="-2.5845091522508E-08" iyy="1.87986725225022E-05" iyz="3.39471452125439E-09" izz="3.17885459163081E-05" />
        </inertial>
        <visual>
            <origin xyz="0 0 0" rpy="0 0 0" />
            <geometry>
                <mesh filename="package://inspire_hand_description/meshes/left/Link6.STL" />
            </geometry>
            <material name="">
                <color rgba="1 1 1 1" />
            </material>
        </visual>
        <collision>
            <origin xyz="0 0 0" rpy="0 0 0" />
            <geometry>
                <mesh filename="package://inspire_hand_description/meshes/left/Link6.STL" />
            </geometry>
        </collision>
    </link>
    <joint name="joint6" type="revolute">
        <origin xyz="0 -0.144 0" rpy="1.5708 0 0" />
        <parent link="Link5" />
        <child link="Link6" />
        <axis xyz="0 0 1" />
        <limit lower="-6.28" upper="6.28" effort="10" velocity="3.92" />
    </joint>
    <joint name="arm_hand_joint" type="fixed">
        <origin xyz="0 0 0" rpy="0 0 0" />
        <!--0.00985 0.02039 0.0404-->
        <parent link="Link6" />
        <child link="left_hand_base" />
    </joint>
    <!-- Create a new base frame for convenience, by LYW, 2019/11/22 -->
    <link name="left_hand_base">
        <!-- Add visual tag for calibration -->
        <!--visual>
      <origin xyz="0 0 -0.025" rpy="0 0 0" />
      <geometry>
        <cylinder radius="0.0279" length="0.05" /> <!- - diameter is 55.8 mm according to the technical specifics- ->
      </geometry>
    </visual-->
    </link>
    <!-- Fix frame of reference through solidworks measurement and manual calibration, by LYW, 2019/11/22 -->
    <joint name="link111_shift" type="fixed">
        <origin xyz="-0.00850 -0.0190 0.0404" rpy="3.1415 0 -1.5707" />
        <!--0.00985 0.02039 0.0404-->
        <parent link="left_hand_base" />
        <child link="link111" />
    </joint>
    <link name="link111">
        <inertial>
            <origin xyz="-0.0211971496867713 -0.00980607468332059 -0.0291539210995797" rpy="0 0 0" />
            <mass value="0.226288892912552" />
            <inertia ixx="0.00025807950453196" ixy="-4.83159310640912E-06" ixz="7.9714751769554E-07" iyy="0.000358691949590454" iyz="3.73467589382574E-06" izz="0.000161017137787831" />
        </inertial>
        <visual>
            <origin xyz="0 0 0" rpy="0 0 0" />
            <geometry>
                <mesh filename="package://inspire_hand_description/meshes/left/link111.STL" />
            </geometry>
            <material name="">
                <color rgba="0.827450980392157 0.83921568627451 0.827450980392157 1" />
            </material>
        </visual>
        <collision>
            <origin xyz="0 0 0" rpy="0 0 0" />
            <geometry>
                <mesh filename="package://inspire_hand_description/meshes/left/link111.STL" />
            </geometry>
        </collision>
    </link>
    <link name="link1">
        <inertial>
            <origin xyz="0.0107728972114067 0.00213787716764519 -1.04416311069722E-07" rpy="0 0 0" />
            <mass value="0.00330630285835291" />
            <inertia ixx="1.55839473420917E-07" ixy="-3.78961194376192E-08" ixz="-3.77173039190185E-12" iyy="5.30393024372046E-07" iyz="-7.4062368302925E-13" izz="5.55170037339627E-07" />
        </inertial>
        <visual>
            <origin xyz="0 0 0" rpy="0 0 0" />
            <geometry>
                <mesh filename="package://inspire_hand_description/meshes/left/link1.STL" />
            </geometry>
            <material name="">
                <color rgba="0.792156862745098 0.819607843137255 0.933333333333333 1" />
            </material>
        </visual>
        <collision>
            <origin xyz="0 0 0" rpy="0 0 0" />
            <geometry>
                <mesh filename="package://inspire_hand_description/meshes/left/link1.STL" />
            </geometry>
        </collision>
    </link>
    <joint name="joint_link1" type="revolute">
        <origin xyz="0.0068852 -0.0077547 -0.08206" rpy="-1.4604 1.2485 -1.466" />
        <parent link="link111" />
        <child link="link1" />
        <axis xyz="0 0 1" />
        <limit lower="-1.6" upper="0" effort="1" velocity="1" />
    </joint>
    <link name="link11">
        <inertial>
            <origin xyz="0.0190179143887291 0.00563447080965412 1.42999243835096E-08" rpy="0 0 0" />
            <mass value="0.00453366979354947" />
            <inertia ixx="8.56969401817861E-08" ixy="-3.6550236316683E-08" ixz="1.43626963228685E-12" iyy="7.5823333421962E-07" iyz="7.37235171817566E-13" izz="7.68832168975162E-07" />
        </inertial>
        <visual>
            <origin xyz="0 0 0" rpy="0 0 0" />
            <geometry>
                <mesh filename="package://inspire_hand_description/meshes/left/link11.STL" />
            </geometry>
            <material name="">
                <color rgba="1 1 1 1" />
            </material>
        </visual>
        <collision>
            <origin xyz="0 0 0" rpy="0 0 0" />
            <geometry>
                <mesh filename="package://inspire_hand_description/meshes/left/link11.STL" />
            </geometry>
        </collision>
    </link>
    <joint name="joint_link11" type="revolute">
        <origin xyz="0.032132 0 0" rpy="-5.2101E-10 -2.8366E-11 -0.05439" />
        <parent link="link1" />
        <child link="link11" />
        <axis xyz="0 0 1" />
        <limit lower="-1.7" upper="0" effort="1" velocity="1" />
    </joint>
    <link name="link2">
        <inertial>
            <origin xyz="0.0107729848426235 0.00213783905889497 -1.15186638033338E-07" rpy="0 0 0" />
            <mass value="0.00330621735666597" />
            <inertia ixx="1.55837836898236E-07" ixy="-3.78957279466946E-08" ixz="-4.46779108562076E-12" iyy="5.30385092299547E-07" iyz="-1.06162548544094E-12" izz="5.5516472017082E-07" />
        </inertial>
        <visual>
            <origin xyz="0 0 0" rpy="0 0 0" />
            <geometry>
                <mesh filename="package://inspire_hand_description/meshes/left/link2.STL" />
            </geometry>
            <material name="">
                <color rgba="0.792156862745098 0.819607843137255 0.933333333333333 1" />
            </material>
        </visual>
        <collision>
            <origin xyz="0 0 0" rpy="0 0 0" />
            <geometry>
                <mesh filename="package://inspire_hand_description/meshes/left/link2.STL" />
            </geometry>
        </collision>
    </link>
    <joint name="joint_link2" type="revolute">
        <origin xyz="-0.012436 -0.0077547 -0.082423" rpy="-1.5708 1.4093 -1.5708" />
        <parent link="link111" />
        <child link="link2" />
        <axis xyz="0 0 1" />
        <limit lower="-1.6" upper="0" effort="1" velocity="1" />
    </joint>
    <link name="link22">
        <inertial>
            <origin xyz="0.0190179449257988 0.00563447974623821 1.95695375043714E-08" rpy="0 0 0" />
            <mass value="0.00453367027223764" />
            <inertia ixx="8.56969657851684E-08" ixy="-3.655092334419E-08" ixz="1.59947670219807E-12" iyy="7.58233058731142E-07" iyz="6.82745605693632E-13" izz="7.68832058388577E-07" />
        </inertial>
        <visual>
            <origin xyz="0 0 0" rpy="0 0 0" />
            <geometry>
                <mesh filename="package://inspire_hand_description/meshes/left/link22.STL" />
            </geometry>
            <material name="">
                <color rgba="1 1 1 1" />
            </material>
        </visual>
        <collision>
            <origin xyz="0 0 0" rpy="0 0 0" />
            <geometry>
                <mesh filename="package://inspire_hand_description/meshes/left/link22.STL" />
            </geometry>
        </collision>
    </link>
    <joint name="joint_link22" type="revolute">
        <origin xyz="0.032132 0 0" rpy="-5.0853E-10 -1.1686E-10 -0.22588" />
        <parent link="link2" />
        <child link="link22" />
        <axis xyz="0 0 1" />
        <limit lower="-1.7" upper="0" effort="1" velocity="1" />
    </joint>
    <link name="link3">
        <inertial>
            <origin xyz="0.0107730870011274 0.00213783984115729 -1.4434440405442E-07" rpy="0 0 0" />
            <mass value="0.00330616517571661" />
            <inertia ixx="1.55836709865158E-07" ixy="-3.78959914486162E-08" ixz="-4.87563626733582E-12" iyy="5.30380857158255E-07" iyz="-1.32040927550488E-12" izz="5.55162479884557E-07" />
        </inertial>
        <visual>
            <origin xyz="0 0 0" rpy="0 0 0" />
            <geometry>
                <mesh filename="package://inspire_hand_description/meshes/left/link3.STL" />
            </geometry>
            <material name="">
                <color rgba="0.792156862745098 0.819607843137255 0.933333333333333 1" />
            </material>
        </visual>
        <collision>
            <origin xyz="0 0 0" rpy="0 0 0" />
            <geometry>
                <mesh filename="package://inspire_hand_description/meshes/left/link3.STL" />
            </geometry>
        </collision>
    </link>
    <joint name="joint_link3" type="revolute">
        <origin xyz="-0.031665 -0.0077547 -0.08192" rpy="-1.9857 1.4406 -1.9826" />
        <parent link="link111" />
        <child link="link3" />
        <axis xyz="0 0 1" />
        <limit lower="-1.6" upper="0" effort="1" velocity="1" />
    </joint>
    <link name="link33">
        <inertial>
            <origin xyz="0.0190179173374263 0.00563447812355383 2.17778843153438E-08" rpy="0 0 0" />
            <mass value="0.00453366946672897" />
            <inertia ixx="8.56969954123567E-08" ixy="-3.65502686172672E-08" ixz="1.914131820864E-12" iyy="7.58232390943582E-07" iyz="6.102905747127E-13" izz="7.68831206632801E-07" />
        </inertial>
        <visual>
            <origin xyz="0 0 0" rpy="0 0 0" />
            <geometry>
                <mesh filename="package://inspire_hand_description/meshes/left/link33.STL" />
            </geometry>
            <material name="">
                <color rgba="1 1 1 1" />
            </material>
        </visual>
        <collision>
            <origin xyz="0 0 0" rpy="0 0 0" />
            <geometry>
                <mesh filename="package://inspire_hand_description/meshes/left/link33.STL" />
            </geometry>
        </collision>
    </link>
    <joint name="joint_link33" type="revolute">
        <origin xyz="0.032132 0 0" rpy="-5.0314E-10 -1.3824E-10 -0.26815" />
        <parent link="link3" />
        <child link="link33" />
        <axis xyz="0 0 1" />
        <limit lower="-1.7" upper="0" effort="1" velocity="1" />
    </joint>
    <link name="link4">
        <inertial>
            <origin xyz="0.0107728838996999 0.00213787812202321 -1.47685512180695E-07" rpy="0 0 0" />
            <mass value="0.00330630460851054" />
            <inertia ixx="1.55839834881808E-07" ixy="-3.78966413485388E-08" ixz="-5.46215465743034E-12" iyy="5.3039377562325E-07" iyz="-1.57695349654339E-12" izz="5.55171477054147E-07" />
        </inertial>
        <visual>
            <origin xyz="0 0 0" rpy="0 0 0" />
            <geometry>
                <mesh filename="package://inspire_hand_description/meshes/left/link4.STL" />
            </geometry>
            <material name="">
                <color rgba="0.792156862745098 0.819607843137255 0.933333333333333 1" />
            </material>
        </visual>
        <collision>
            <origin xyz="0 0 0" rpy="0 0 0" />
            <geometry>
                <mesh filename="package://inspire_hand_description/meshes/left/link4.STL" />
            </geometry>
        </collision>
    </link>
    <joint name="joint_link4" type="revolute">
        <origin xyz="-0.050841 -0.0077547 -0.08041" rpy="-2.0186 1.327 -2.007" />
        <parent link="link111" />
        <child link="link4" />
        <axis xyz="0 0 1" />
        <limit lower="-1.6" upper="0" effort="1" velocity="1" />
    </joint>
    <link name="link44">
        <inertial>
            <origin xyz="0.0155924434001128 0.00555617869155978 -1.05483765444614E-07" rpy="0 0 0" />
            <mass value="0.00356888715893842" />
            <inertia ixx="6.67772840408144E-08" ixy="-2.70391833548355E-08" ixz="-3.26434716125092E-12" iyy="4.33419425101179E-07" iyz="-9.18888508148905E-13" izz="4.39763878420807E-07" />
        </inertial>
        <visual>
            <origin xyz="0 0 0" rpy="0 0 0" />
            <geometry>
                <mesh filename="package://inspire_hand_description/meshes/left/link44.STL" />
            </geometry>
            <material name="">
                <color rgba="1 1 1 1" />
            </material>
        </visual>
        <collision>
            <origin xyz="0 0 0" rpy="0 0 0" />
            <geometry>
                <mesh filename="package://inspire_hand_description/meshes/left/link44.STL" />
            </geometry>
        </collision>
    </link>
    <joint name="joint_link44" type="revolute">
        <origin xyz="0.032132 0 0" rpy="-5.1334E-10 -9.3483E-11 -0.18013" />
        <parent link="link4" />
        <child link="link44" />
        <axis xyz="0 0 1" />
        <limit lower="-1.7" upper="0" effort="1" velocity="1" />
    </joint>
    <link name="link5">
        <inertial>
            <origin xyz="-0.00433166459951286 0.000656790554769388 -0.000486675184306562" rpy="0 0 0" />
            <mass value="0.00487393910083768" />
            <inertia ixx="1.30409345970056E-07" ixy="8.91998160729811E-09" ixz="1.76607007575074E-08" iyy="1.7058032498292E-07" iyz="-1.02771404037179E-09" izz="2.11710622768954E-07" />
        </inertial>
        <visual>
            <origin xyz="0 0 0" rpy="0 0 0" />
            <geometry>
                <mesh filename="package://inspire_hand_description/meshes/left/link5.STL" />
            </geometry>
            <material name="">
                <color rgba="0.827450980392157 0.83921568627451 0.827450980392157 1" />
            </material>
        </visual>
        <collision>
            <origin xyz="0 0 0" rpy="0 0 0" />
            <geometry>
                <mesh filename="package://inspire_hand_description/meshes/left/link5.STL" />
            </geometry>
        </collision>
    </link>
    <joint name="joint_link5" type="revolute">
        <origin xyz="0.0010638 -0.025 -0.0059231" rpy="-1.5708 -2.455E-15 2.3555" />
        <parent link="link111" />
        <child link="link5" />
        <axis xyz="0 -1 0" />
        <limit lower="-1.0" upper="0.3" effort="1" velocity="1" />
    </joint>
    <link name="link51">
        <inertial>
            <origin xyz="0.0261736471642429 0.00353664240332538 -7.35522423800372E-08" rpy="0 0 0" />
            <mass value="0.00652741708580189" />
            <inertia ixx="8.93663478287007E-07" ixy="6.28882108303181E-08" ixz="-3.67789097092471E-11" iyy="2.37350868720489E-06" iyz="8.30149702319962E-12" izz="2.7502170955408E-06" />
        </inertial>
        <visual>
            <origin xyz="0 0 0" rpy="0 0 0" />
            <geometry>
                <mesh filename="package://inspire_hand_description/meshes/left/link51.STL" />
            </geometry>
            <material name="">
                <color rgba="0.792156862745098 0.819607843137255 0.933333333333333 1" />
            </material>
        </visual>
        <collision>
            <origin xyz="0 0 0" rpy="0 0 0" />
            <geometry>
                <mesh filename="package://inspire_hand_description/meshes/left/link51.STL" />
            </geometry>
        </collision>
    </link>
    <joint name="joint_link51" type="revolute">
        <origin xyz="-0.0115 -0.00075 0" rpy="-1.4988E-15 -5.5511E-17 1.8988" />
        <parent link="link5" />
        <child link="link51" />
        <axis xyz="0 0 -1" />
        <limit lower="-0.8" upper="0.4" effort="1" velocity="1" />
    </joint>
    <link name="link52">
        <inertial>
            <origin xyz="-0.00731595394729753 -0.00552216810488045 1.31327036717588E-07" rpy="0 0 0" />
            <mass value="0.00226947954597765" />
            <inertia ixx="1.72809908882086E-07" ixy="4.52296648937248E-08" ixz="-3.78399670014347E-12" iyy="2.78044490402836E-07" iyz="1.5225345233066E-13" izz="2.99628844053565E-07" />
        </inertial>
        <visual>
            <origin xyz="0 0 0" rpy="0 0 0" />
            <geometry>
                <mesh filename="package://inspire_hand_description/meshes/left/link52.STL" />
            </geometry>
            <material name="">
                <color rgba="0.827450980392157 0.83921568627451 0.827450980392157 1" />
            </material>
        </visual>
        <collision>
            <origin xyz="0 0 0" rpy="0 0 0" />
            <geometry>
                <mesh filename="package://inspire_hand_description/meshes/left/link52.STL" />
            </geometry>
        </collision>
    </link>
    <joint name="joint_link52" type="revolute">
        <origin xyz="0.056001 0 0" rpy="-1.3323E-15 -2.7756E-17 -3.0416" />
        <parent link="link51" />
        <child link="link52" />
        <axis xyz="0 0 1" />
        <limit lower="-0.4" upper="0" effort="1" velocity="1" />
    </joint>
    <link name="link53">
        <inertial>
            <origin xyz="0.0104629360450728 0.00192820283562468 -3.38351464429509E-06" rpy="0 0 0" />
            <mass value="0.00330869122519449" />
            <inertia ixx="8.21794532311926E-08" ixy="1.14153196955289E-08" ixz="-1.49218673904795E-10" iyy="1.90093466236439E-07" iyz="3.77060351806357E-11" izz="1.96169077984371E-07" />
        </inertial>
        <visual>
            <origin xyz="0 0 0" rpy="0 0 0" />
            <geometry>
                <mesh filename="package://inspire_hand_description/meshes/left/link53.STL" />
            </geometry>
            <material name="">
                <color rgba="0.827450980392157 0.83921568627451 0.827450980392157 1" />
            </material>
        </visual>
        <collision>
            <origin xyz="0 0 0" rpy="0 0 0" />
            <geometry>
                <mesh filename="package://inspire_hand_description/meshes/left/link53.STL" />
            </geometry>
        </collision>
    </link>
    <joint name="joint_link53" type="revolute">
        <origin xyz="-0.022653 0 0" rpy="1.2712E-14 -9.7145E-17 2.856" />
        <parent link="link52" />
        <child link="link53" />
        <axis xyz="0 0 1" />
        <limit lower="-1" upper="0" effort="1" velocity="1" />
    </joint>
    <transmission name="trans_joint1">
        <type>transmission_interface/SimpleTransmission</type>
        <joint name="joint1">
            <hardwareInterface>hardware_interface/PositionJointInterface</hardwareInterface>
        </joint>
        <actuator name="joint1_motor">
            <hardwareInterface>hardware_interface/PositionJointInterface</hardwareInterface>
            <mechanicalReduction>1</mechanicalReduction>
        </actuator>
    </transmission>
    <transmission name="trans_joint2">
        <type>transmission_interface/SimpleTransmission</type>
        <joint name="joint2">
            <hardwareInterface>hardware_interface/PositionJointInterface</hardwareInterface>
        </joint>
        <actuator name="joint2_motor">
            <hardwareInterface>hardware_interface/PositionJointInterface</hardwareInterface>
            <mechanicalReduction>1</mechanicalReduction>
        </actuator>
    </transmission>
    <transmission name="trans_joint3">
        <type>transmission_interface/SimpleTransmission</type>
        <joint name="joint3">
            <hardwareInterface>hardware_interface/PositionJointInterface</hardwareInterface>
        </joint>
        <actuator name="joint3_motor">
            <hardwareInterface>hardware_interface/PositionJointInterface</hardwareInterface>
            <mechanicalReduction>1</mechanicalReduction>
        </actuator>
    </transmission>
    <transmission name="trans_joint4">
        <type>transmission_interface/SimpleTransmission</type>
        <joint name="joint4">
            <hardwareInterface>hardware_interface/PositionJointInterface</hardwareInterface>
        </joint>
        <actuator name="joint4_motor">
            <hardwareInterface>hardware_interface/PositionJointInterface</hardwareInterface>
            <mechanicalReduction>1</mechanicalReduction>
        </actuator>
    </transmission>
    <transmission name="trans_joint5">
        <type>transmission_interface/SimpleTransmission</type>
        <joint name="joint5">
            <hardwareInterface>hardware_interface/PositionJointInterface</hardwareInterface>
        </joint>
        <actuator name="joint5_motor">
            <hardwareInterface>hardware_interface/PositionJointInterface</hardwareInterface>
            <mechanicalReduction>1</mechanicalReduction>
        </actuator>
    </transmission>
    <transmission name="trans_joint6">
        <type>transmission_interface/SimpleTransmission</type>
        <joint name="joint6">
            <hardwareInterface>hardware_interface/PositionJointInterface</hardwareInterface>
        </joint>
        <actuator name="joint6_motor">
            <hardwareInterface>hardware_interface/PositionJointInterface</hardwareInterface>
            <mechanicalReduction>1</mechanicalReduction>
        </actuator>
    </transmission>
    <transmission name="trans_joint_link1">
        <type>transmission_interface/SimpleTransmission</type>
        <joint name="joint_link1">
            <hardwareInterface>hardware_interface/PositionJointInterface</hardwareInterface>
        </joint>
        <actuator name="joint_link1_motor">
            <hardwareInterface>hardware_interface/PositionJointInterface</hardwareInterface>
            <mechanicalReduction>1</mechanicalReduction>
        </actuator>
    </transmission>
    <transmission name="trans_joint_link11">
        <type>transmission_interface/SimpleTransmission</type>
        <joint name="joint_link11">
            <hardwareInterface>hardware_interface/PositionJointInterface</hardwareInterface>
        </joint>
        <actuator name="joint_link11_motor">
            <hardwareInterface>hardware_interface/PositionJointInterface</hardwareInterface>
            <mechanicalReduction>1</mechanicalReduction>
        </actuator>
    </transmission>
    <transmission name="trans_joint_link2">
        <type>transmission_interface/SimpleTransmission</type>
        <joint name="joint_link2">
            <hardwareInterface>hardware_interface/PositionJointInterface</hardwareInterface>
        </joint>
        <actuator name="joint_link2_motor">
            <hardwareInterface>hardware_interface/PositionJointInterface</hardwareInterface>
            <mechanicalReduction>1</mechanicalReduction>
        </actuator>
    </transmission>
    <transmission name="trans_joint_link22">
        <type>transmission_interface/SimpleTransmission</type>
        <joint name="joint_link22">
            <hardwareInterface>hardware_interface/PositionJointInterface</hardwareInterface>
        </joint>
        <actuator name="joint_link22_motor">
            <hardwareInterface>hardware_interface/PositionJointInterface</hardwareInterface>
            <mechanicalReduction>1</mechanicalReduction>
        </actuator>
    </transmission>
    <transmission name="trans_joint_link3">
        <type>transmission_interface/SimpleTransmission</type>
        <joint name="joint_link3">
            <hardwareInterface>hardware_interface/PositionJointInterface</hardwareInterface>
        </joint>
        <actuator name="joint_link3_motor">
            <hardwareInterface>hardware_interface/PositionJointInterface</hardwareInterface>
            <mechanicalReduction>1</mechanicalReduction>
        </actuator>
    </transmission>
    <transmission name="trans_joint_link33">
        <type>transmission_interface/SimpleTransmission</type>
        <joint name="joint_link33">
            <hardwareInterface>hardware_interface/PositionJointInterface</hardwareInterface>
        </joint>
        <actuator name="joint_link33_motor">
            <hardwareInterface>hardware_interface/PositionJointInterface</hardwareInterface>
            <mechanicalReduction>1</mechanicalReduction>
        </actuator>
    </transmission>
    <transmission name="trans_joint_link4">
        <type>transmission_interface/SimpleTransmission</type>
        <joint name="joint_link4">
            <hardwareInterface>hardware_interface/PositionJointInterface</hardwareInterface>
        </joint>
        <actuator name="joint_link4_motor">
            <hardwareInterface>hardware_interface/PositionJointInterface</hardwareInterface>
            <mechanicalReduction>1</mechanicalReduction>
        </actuator>
    </transmission>
    <transmission name="trans_joint_link44">
        <type>transmission_interface/SimpleTransmission</type>
        <joint name="joint_link44">
            <hardwareInterface>hardware_interface/PositionJointInterface</hardwareInterface>
        </joint>
        <actuator name="joint_link44_motor">
            <hardwareInterface>hardware_interface/PositionJointInterface</hardwareInterface>
            <mechanicalReduction>1</mechanicalReduction>
        </actuator>
    </transmission>
    <transmission name="trans_joint_link5">
        <type>transmission_interface/SimpleTransmission</type>
        <joint name="joint_link5">
            <hardwareInterface>hardware_interface/PositionJointInterface</hardwareInterface>
        </joint>
        <actuator name="joint_link5_motor">
            <hardwareInterface>hardware_interface/PositionJointInterface</hardwareInterface>
            <mechanicalReduction>1</mechanicalReduction>
        </actuator>
    </transmission>
    <transmission name="trans_joint_link51">
        <type>transmission_interface/SimpleTransmission</type>
        <joint name="joint_link51">
            <hardwareInterface>hardware_interface/PositionJointInterface</hardwareInterface>
        </joint>
        <actuator name="joint_link51_motor">
            <hardwareInterface>hardware_interface/PositionJointInterface</hardwareInterface>
            <mechanicalReduction>1</mechanicalReduction>
        </actuator>
    </transmission>
    <transmission name="trans_joint_link52">
        <type>transmission_interface/SimpleTransmission</type>
        <joint name="joint_link52">
            <hardwareInterface>hardware_interface/PositionJointInterface</hardwareInterface>
        </joint>
        <actuator name="joint_link52_motor">
            <hardwareInterface>hardware_interface/PositionJointInterface</hardwareInterface>
            <mechanicalReduction>1</mechanicalReduction>
        </actuator>
    </transmission>
    <transmission name="trans_joint_link53">
        <type>transmission_interface/SimpleTransmission</type>
        <joint name="joint_link53">
            <hardwareInterface>hardware_interface/PositionJointInterface</hardwareInterface>
        </joint>
        <actuator name="joint_link53_motor">
            <hardwareInterface>hardware_interface/PositionJointInterface</hardwareInterface>
            <mechanicalReduction>1</mechanicalReduction>
        </actuator>
    </transmission>
    <gazebo>
        <plugin name="gazebo_ros_control" filename="libgazebo_ros_control.so">
            <robotNamespace>/</robotNamespace>
        </plugin>
    </gazebo>
    
    <gazebo>
     <plugin name="gazebo_grasp_fix" filename="libgazebo_grasp_fix.so">
           <arm>
             <arm_name>RM65</arm_name>
             <palm_link>left_hand_base</palm_link>
             <gripper_link>joint_link44</gripper_link>
             <gripper_link>joint_link4</gripper_link>
             <gripper_link>joint_link22</gripper_link>
             <gripper_link>joint_link2</gripper_link>
             <gripper_link>joint_link11</gripper_link>
             <gripper_link>joint_link1</gripper_link>
             <gripper_link>joint_link3</gripper_link>
             <gripper_link>joint_link33</gripper_link>
             <gripper_link>joint_link5</gripper_link>
             <gripper_link>joint_link51</gripper_link>
             <gripper_link>joint_link52</gripper_link>
             <gripper_link>joint_link53</gripper_link>
           </arm>
       <forces_angle_tolerance>10</forces_angle_tolerance>
       <update_rate>130</update_rate>
       <grip_count_threshold>2</grip_count_threshold>
       <max_grip_count>8</max_grip_count>
       <release_tolerance>0.01</release_tolerance>
       <disable_collisions_on_attach>true</disable_collisions_on_attach>
       <contact_topic>__default_topic__</contact_topic>
     </plugin>
   </gazebo>
    
</robot>

